---
layout: post
category: Go
title: go的panic和recover
---

## 什么是 panic？

在 Go 语言中，程序中一般是使用错误来处理异常情况。对于程序中出现的大部分异常情况，错误就已经够用了。

但在有些情况，当程序发生异常时，无法继续运行。在这种情况下，我们会使用 panic 来终止程序。当函数发生 panic 时，它会终止运行，在执行完所有的延迟函数后，程序控制返回到该函数的调用方。这样的过程会一直持续下去，直到当前协程的所有函数都返回退出，然后程序会打印出 panic 信息，接着打印出堆栈跟踪（Stack Trace），最后程序终止。在编写一个示例程序后，我们就能很好地理解这个概念了。

在本教程里，我们还会接着讨论，当程序发生 panic 时，使用 recover 可以重新获得对该程序的控制。

可以认为 panic 和 recover 与其他语言中的 try-catch-finally 语句类似，只不过一般我们很少使用 panic 和 recover。而当我们使用了 panic 和 recover 时，也会比 try-catch-finally 更加优雅，代码更加整洁。

## 什么时候应该使用 panic？

需要注意的是，你应该尽可能地使用错误，而不是使用 panic 和 recover。只有当程序不能继续运行的时候，才应该使用 panic 和 recover 机制。

panic 有两个合理的用例。

发生了一个不能恢复的错误，此时程序不能继续运行。 一个例子就是 web 服务器无法绑定所要求的端口。在这种情况下，就应该使用 panic，因为如果不能绑定端口，啥也做不了。

发生了一个编程上的错误。 假如我们有一个接收指针参数的方法，而其他人使用 nil 作为参数调用了它。在这种情况下，我们可以使用 panic，因为这是一个编程错误：用 nil 参数调用了一个只能接收合法指针的方法。

## 发生 panic 时的 defer

我们重新总结一下 panic 做了什么。当函数发生 panic 时，它会终止运行，在执行完所有的延迟函数后，程序控制返回到该函数的调用方。这样的过程会一直持续下去，直到当前协程的所有函数都返回退出，然后程序会打印出 panic 信息，接着打印出堆栈跟踪，最后程序终止。

在上面的例子中，我们没有延迟调用任何函数。如果有延迟函数，会先调用它，然后程序控制返回到函数调用方。

## recover

recover 是一个内建函数，用于重新获得 panic 协程的控制。

recover 函数的标签如下所示：

    func recover() interface{}

只有在延迟函数的内部，调用 recover 才有用。在延迟函数内调用 recover，可以取到 panic 的错误信息，并且停止 panic 续发事件（Panicking Sequence），程序运行恢复正常。如果在延迟函数的外部调用 recover，就不能停止 panic 续发事件。

我们来修改一下程序，在发生 panic 之后，使用 recover 来恢复正常的运行。

```go
package main

import (  
    "fmt"
)

func recoverName() {  
    if r := recover(); r!= nil {
        fmt.Println("recovered from ", r)
    }
}

func fullName(firstName *string, lastName *string) {  
    defer recoverName()
    if firstName == nil {
        panic("runtime error: first name cannot be nil")
    }
    if lastName == nil {
        panic("runtime error: last name cannot be nil")
    }
    fmt.Printf("%s %s\n", *firstName, *lastName)
    fmt.Println("returned normally from fullName")
}

func main() {  
    defer fmt.Println("deferred call in main")
    firstName := "Elon"
    fullName(&firstName, nil)
    fmt.Println("returned normally from main")
}
```